Добрый день,

вы меня немного не так поняли, вот я разбирал ваш метод: 

getUserInfo() {
    // если тут нет связи с сервером то сразу попадаем в catch внутри класса
    return fetch('https://praktikum.tk/cohort9/users/me', this.options)
      .then(res => {
        if (res.ok) {
          return res.json();

        }
        // А этот reject ведет нас уже в catch в точку вызова, а не в тот, что ниже
        // Сервер то ответ дал, просто плохой
        // +++++++++++++++++++++++++++++++++++++++++++++
        // Promise.reject вы зря убрали, верните!!!!!
        // Этот реджект тоже нужен, он как раз возвращает ошибку если получен,
        // например, 404 от сервера, когда сервер ответил, но ресурс не найден.
        return Promise.reject(`Ошибка: ${res.status}`); 
        // +++++++++++++++++++++++++++++++++++++++++++++
      })
      .catch(err => {
        // А тут надо добавить возврат ошибки, чтобы в точке вызова мы тоже попапли в catch
        console.log(err);
      })

Сейчас, когда вы убрали "ненужный" реджект, ваш Api примет любую ошибку сервера не связанную с подключением, проверит res.ok, естественно условие не выполнися, но раньше после него вы возвращали реджект, который говорил точке вызова "данных нет", а сейчас т.к. после if нет return ваш Api вернет undefined, который попадет в точку вызова, и там упадет в catch не потому что интерпретатор такой умный, а потому что в then точке вызова возникнет ошибка, вызванная некорректными данными, и ее там catch и поймает. Может чуть сложно, но вы должны понять что then и catch это суть функции, и им должно иметь return на все случаи жизни.

Это надо исправить. А еще аватара у вас теперь почуму не загружается с сервера? Это в первом обязательном пункте брифа написано, поэтому будьте добры сделайте. 
